Workbook

Sheet Summary
A3: =TODAY() -> 46123
A4: Fnc Stores Inventory / جرد مخازن الشركة الوطنية الأولى
A6: # | B6: Store | C6: Total
A7: 1 | B7: مخزن حديد / Steel Store | C7: ='Steel Store'!$G$66 -> 44902.184
A8: 2 | B8: مخزن مواد عامة / General Store | C8: ='General Store'!$G$407 -> 42574.228
A9: 3 | B9: Electrical Equipments Store / مخزن مواد الكهرباء | C9: ='Electrical Equipment Store'!$G$801 -> 255586.77
A10: 4 | B10: مخزن صحيات / Plumbing Store | C10: ='Plumbing Store'!$G$828 -> 43779.062
A11: 5 | B11: PVC Store/ مخزن بي في سي والمنيوم | C11: ='PVC Store'!$G$113 -> 12423.709
A12: 6 | B12: مخزن اصباغ / Paint store | C12: ='Paint Store'!$G$140 -> 109831.15
A13: 7 | B13: مخزن سبالت / AC Unit store | C13: ='AC Unit Store'!$G$75 -> 23262.531
A14: 8 | B14: مخزن اثاث /Furniture Store | C14: ='Furniture Store'!$G$16 -> 9534.68
A15: 9 | B15: مخزن معدات العمل / Work Tools Store | C15: ='Work Tools Store '!G51 -> 8571
A16: 10 | B16: مخزن ساندوج , بليوود , فاينل , اليكوبون /Sandwich , Plywood ,Vinyl & Alucobond | C16: ='Sandwich , Plywood ,Vinyl'!$G$181 -> 105199.64
A17: 11 | B17: مخزن معدات السلامة / Safety Store | C17: ='Safety Store'!$G$119 -> 5068.1624
A18: 12 | B18: مخزن مواد بناء عامة / General Construction Store | C18: ='General Construction Store'!$G$111 -> 46936.087
A19: 13 | B19: مخزن مواد تنظيف / Cleaning Materials Store | C19: ='Cleaning Materials Store '!$G$21 -> 1076.523
A20: 14 | B20: كابلات سقيفة المعمل (شبه مستعملة) /Outside Area Cables ( Like New ) | C20: ='Outside Area Cables'!$H$163 -> 28455.76
A22: Total | C22: =SUM(C7:C20) -> 737201.48

Sheet Steel Store
A2: =TODAY() -> 46123
A3: مخزن حديد / steel Store
A4: ت | B4: (اسم المادة ) | C4: (Subject Name) | D4: الوحدة Unit | E4: Rate Per Unit القيمة لكل وحدة | F4: الكمية Qty | G4: Total Unit المجموع | H4: Remark
A5: 1 | B5: زاوية 5*5 2 ملم | C5: ANGLE 5*5*2MM , 6mt | D5: EA | E5: =[1]Summary!E4 -> 9.5 | F5: =[1]Summary!F4 -> 0 | G5: =E5*F5 -> 0
A6: 2 | B6: زاوية 5*5 3 ملم | C6: ANGLE 5*5*3MM , 6mt | D6: EA | E6: =[1]Summary!E5 -> 12 | F6: =[1]Summary!F5 -> 0 | G6: =E6*F6 -> 0
A7: 3 | B7: زاوية 7*7 4 ملم | C7: ANGLE 7*7*4MM , 6mt | D7: EA | E7: =[1]Summary!E6 -> 19 | F7: =[1]Summary!F6 -> 0 | G7: =E7*F7 -> 0
A8: 4 | B8: زاوية 8*8 6 ملم | C8: ANGLE 8*8*6MM , 6mt | D8: EA | E8: =[1]Summary!E7 -> 40 | F8: =[1]Summary!F7 -> 0 | G8: =E8*F8 -> 0
A9: 5 | B9: زاوية 10 * 10 سم 10 ملم | C9: ANGLE 10*10*10 mm ,6mt | D9: EA | E9: =[1]Summary!E8 -> 78 | F9: =[1]Summary!F8 -> 0.298 | G9: =E9*F9 -> 23.244
A10: 6 | B10: زاوية 3* 3 سم 2 ملم + كلفنايز | C10: ANGLE 3*3*2MM + galvanize , 6mt + 3m | D10: EA | E10: =[1]Summary!E9 -> 4 | F10: =[1]Summary!F9 -> 0 | G10: =E10*F10 -> 0
A11: 7 | B11: بوري كلفنايز 4*4 سم 2 ملم | C11: GAL. Pipe 4*4*2MM | D11: EA | E11: =[1]Summary!E10 -> 13.5 | F11: =[1]Summary!F10 -> 0 | G11: =E11*F11 -> 0
A12: 8 | B12: بوري كلفنايز 4*6 سم 2 ملم | C12: GAL. Pipe 6*4*2MM | D12: EA | E12: =[1]Summary!E11 -> 19 | F12: =[1]Summary!F11 -> 0 | G12: =E12*F12 -> 0
A13: 9 | B13: بوري كلفنايز 4*8 سم 2 ملم | C13: GAL. Pipe 4*8*2MM | D13: EA | E13: =[1]Summary!E12 -> 22 | F13: =[1]Summary!F12 -> 0 | G13: =E13*F13 -> 0
A14: 10 | B14: بوري كلفنايز4*2 2ملم | C14: Galvanis Pipe 4*2 2mm | D14: EA | E14: =[1]Summary!E13 -> 12 | F14: =[1]Summary!F13 -> 0 | G14: =E14*F14 -> 0
A15: 11 | B15: شلمان 10 سم 6 متر | C15: I-BEAM 10*20 | D15: EA | E15: =[1]Summary!E14 -> 35 | F15: =[1]Summary!F14 -> 1.25 | G15: =E15*F15 -> 43.75
A16: 12 | B16: شلمان 20 سم 12 متر | C16: I-BEAM 20*40 | D16: EA | E16: =[1]Summary!E15 -> 245 | F16: =[1]Summary!F15 -> 0.35 | G16: =E16*F16 -> 85.75
... A64: 60 | B64: شلمان 22 سم 12 متر | C64: I-BEAM 22 | D64: EA | E64: =[1]Summary!E63 -> 285 | F64: =[1]Summary!F63 -> 0.434 | G64: =E64*F64 -> 123.69
A66: Total | F66: =SUM(F5:F64) -> 927.99 | G66: =SUM(G7:G64) -> 44902.184

Sheet General Store
A2: =TODAY() -> 46123
A3: مخزن مواد عامة / General Store
A4: ت | B4: (اسم المادة ) | C4: (Subject Name) | D4: الوحدة Unit | E4: Rate Per Unit القيمة لكل وحدة | F4: الكمية Qty | G4: Total Unit المجموع | H4: Type النوع
A5: 1 | B5: كندك حجم كبير تولسن "12 | C5: Adjustable Ind Wrench 12" Tolse | D5: EA | E5: =[2]Summary!E4 -> 7.5 | F5: =[2]Summary!F4 -> 0 | G5: =F5*E5 -> 0 | H5: ادوات
A6: 2 | B6: كندك حجم كبير تروبر "12 | C6: Adjustable Wrench 12" Truper | D6: EA | E6: =[2]Summary!E5 -> 2.15 | F6: =[2]Summary!F5 -> 4 | G6: =F6*E6 -> 8.6 | H6: اداوت
A7: 3 | B7: بلايس متغير "10 تروبير | C7: Ajustable Joint Trupper 10" | D7: EA | E7: =[2]Summary!E6 -> 6.99 | F7: =[2]Summary!F6 -> 0 | G7: =F7*E7 -> 0 | H7: اداوت
A8: 4 | B8: بلايس متغير "12 تروبير | C8: Ajustable Joint Trupper 12" | D8: EA | E8: =[2]Summary!E7 -> 3.6 | F8: =[2]Summary!F7 -> 0 | G8: =F8*E8 -> 0 | H8: اداوت
A9: 5 | B9: بلايس متغير "8 تروبير | C9: Ajustable Joint Trupper 8" | D9: EA | E9: =[2]Summary!E8 -> 13 | F9: =[2]Summary!F8 -> 0 | G9: =F9*E9 -> 0 | H9: اداوت
A10: 6 | B10: زاوية قياس حدادين | C10: Aluminum Ruler With Angle Bar S | D10: EA | E10: =[2]Summary!E9 -> 3.37 | F10: =[2]Summary!F9 -> 0 | G10: =F10*E10 -> 0 | H10: اداوت
A11: 7 | B11: انكر بولت 16ملم 50سم 10*50سم | C11: Ancher Bolt 16mm 50cm 50 10cm | D11: EA | E11: =[2]Summary!E10 -> 0.907 | F11: =[2]Summary!F10 -> 0 | G11: =F11*E11 -> 0 | H11: انكر بولت
A12: 8 | B12: انكر بولت 18ملم | C12: Ancher Bolt 18mm | D12: EA | E12: =[2]Summary!E11 -> 1.125 | F12: =[2]Summary!F11 -> 8 | G12: =F12*E12 -> 9 | H12: انكر بولت
A13: 9 | B13: انكر بولت 22ملم | C13: Ancher Bolt 22mm | D13: EA | E13: =[2]Summary!E12 -> 1.2 | F13: =[2]Summary!F12 -> 0 | G13: =F13*E13 -> 0 | H13: انكر بولت
A14: 10 | B14: زاوية حاملة رف ستيل 15.2*20.3سم L | C14: Angle Shelf Holder 15.2 20.3cm | D14: EA | E14: =[2]Summary!E13 -> 1.02 | F14: =[2]Summary!F13 -> 0 | G14: =F14*E14 -> 0 | H14: اداوت
A15: 11 | B15: بوربرين | C15: Ball Bearing | D15: EA | E15: =[2]Summary!E14 -> 3 | F15: =[2]Summary!F14 -> 4 | G15: =F15*E15 -> 12 | H15: اداوت
A16: 12 | B16: كلابتين | C16: Big End Cutting Pliers | D16: EA | E16: =[2]Summary!E15 -> 9 | F16: =[2]Summary!F15 -> 0 | G16: =F16*E16 -> 0 | H16: اداوت
... A31: 27 | B31: حجر كتر بي في سي | C31: Blade Saw PVC (CD) 500*320 | D31: EA | E31: =[2]Summary!E30 -> 30 | F31: =[2]Summary!F30 -> 5 | G31: =F31*E31 -> 150 | H31: احجار
A32: 28 | B32: برغي 6*160 خشابي | C32: ='[2]Bolt 160 6mm'!$K$3 -> Bolt 160 * 6mm | D32: EA | E32: =[2]Summary!E31 -> 3 | F32: =[2]Summary!F31 -> 0 | G32: =F32*E32 -> 0 | H32: براغي متنوع
A33: 29 | B33: برغي 100 *6.3 ملم | C33: Bolt 100 * 6.3mm | D33: Package | E33: =[2]Summary!E32 -> 14.2 | F33: =[2]Summary!F32 -> 6.5 | G33: =F33*E33 -> 92.3 | H33: برغي لقمة
A34: 30 | B34: برغي 10ملم كلفنايز | C34: Bolt 10mm | D34: Kilo | E34: =[2]Summary!E33 -> 1.5 | F34: =[2]Summary!F33 -> 0 | G34: =F34*E34 -> 0 | H34: براغي متنوع
A35: 31 | B35: براغي واشر ونت واشر سبرنك ورولط بولت | C35: Bolt 10mm +Nut+ Washer | D35: Kilo | E35: =[2]Summary!E34 -> 1.7 | F35: =[2]Summary!F34 -> 0 | G35: =F35*E35 -> 0 | H35: براغي متنوع
A36: 32 | B36: براغي سلفر 10ملم 13 سم ونت واشر دبل | C36: Bolt 10mm 13cm Silver +Nut+Double Washer | D36: EA | E36: =[2]Summary!E35 -> 0.159 | F36: =[2]Summary!F35 -> 476.7 | G36: =F36*E36 -> 75.7953 | H36: براغي متنوع
A37: 33 | B37: برغي 10ملم *20سم | C37: Bolt 10mm*20cm | D37: EA | E37: =[2]Summary!E36 -> 2 | F37: =[2]Summary!F36 -> 2.4 | G37: =F37*E37 -> 4.8 | H37: براغي متنوع
A38: 34 | B38: برغي 10ملم *4سم وواشر سبرينك ونت اسود | C38: Bolt 10mm 4cm Washer Spring Nut Black | D38: EA | E38: =[2]Summary!E37 -> 1.6 | F38: =[2]Summary!F37 -> 0 | G38: =F38*E38 -> 0 | H38: براغي متنوع
A39: 35 | B39: برغي 125 *6.3 ملم | C39: Bolt 125 * 6.3mm | D39: Package | E39: =[2]Summary!E38 -> 13.3 | F39: =[2]Summary!F38 -> 151.5 | G39: =F39*E39 -> 2014.95 | H39: برغي لقمة
A40: 36 | B40: برغي 12 ملم | C40: Bolt 12mm | D40: EA | E40: =[2]Summary!E39 -> 1.6 | F40: =[2]Summary!F39 -> 0 | G40: =F40*E40 -> 0 | H40: براغي متنوع
A41: 37 | B41: برغي 3.9 *13 ملم | C41: Bolt 13 * 3.9mm | D41: Package | E41: =[2]Summary!E40 -> 7 | F41: =[2]Summary!F40 -> 1 | G41: =F41*E41 -> 7 | H41: برغي خشب
A42: 38 | B42: برغي 13 *4.2 ملم | C42: Bolt 13 * 4.2mm | D42: Package | E42: =[2]Summary!E41 -> 2.25 | F42: =[2]Summary!F41 -> 12 | G42: =F42*E42 -> 27 | H42: برغي سمنت بورد
A43: 39 | B43: برغي اسود 8.8 | C43: Bolt 14mm 12.5 cm | D43: Kilo | E43: =[2]Summary!E42 -> 2.381 | F43: =[2]Summary!F42 -> 0 | G43: =F43*E43 -> 0 | H43: براغي متنوع
A44: 40 | B44: برغي 150 *6.3 ملم | C44: Bolt 150 * 6.3mm | D44: Package | E44: =[2]Summary!E43 -> 15 | F44: =[2]Summary!F43 -> 2 | G44: =F44*E44 -> 30 | H44: برغي لقمة
... A405: 401 | B405: بسمار اندوفيلا 8ملم قهوائي | C405: Nail Onduvilla 8mm Brown | D405: Package | E405: =[2]Summary!E404 -> 5.2 | F405: =[2]Summary!F404 -> 3 | G405: =F405*E405 -> 15.6 | H405: بسامير
A407: Total | F407: =SUM(F5:F405) -> 19671.69 | G407: =SUM(G5:G405) -> 42574.228

Sheet Electrical Equipment Store
A2: =TODAY() -> 46123
A3: Electrical Equipments Store - مخزن مواد الكهرباء
A4: ت | B4: اسم المادة | C4: Subject Name | D4: الوحدة Unit | E4: Rate per Unit | F4: الكمية .Qty | G4: total | H4: Type | I4: Remark
A5: 1 | B5: حساس دخان + حراري باكيت ابيض مع باتري | C5: Photoelectric smoke and heat alarm | D5: No. | E5: =[3]Summary!E4 -> 0 | F5: =[3]Summary!F4 -> 19 | G5: =F5*E5 -> 0 | H5: Detectors
A6: 2 | B6: كيبل منظومة حريق | C6: Alarm Cable 1 2 1.5 0.80 FE180 | D6: No. | E6: =[3]Summary!E5 -> 325 | F6: =[3]Summary!F5 -> 0 | G6: =F6*E6 -> 0 | H6: Fire System
A7: 3 | B7: زاوية حمالة تراي كيبل 10سم | C7: Angle Handle Iron Trunking Cable 10cm | D7: No. | E7: =[3]Summary!E6 -> 0 | F7: =[3]Summary!F6 -> 2 | G7: =F7*E7 -> 0 | H7: Cable tray
A8: 4 | B8: تيرمينال حلقي وشوكي ملون مختلف الاحجام | C8: Annular&Fork Terminal Different Size | D8: No. | E8: =[3]Summary!E7 -> 7.25 | F8: =[3]Summary!F7 -> 0 | G8: =F8*E8 -> 0 | H8: Cable Connectors
A9: 5 | B9: مانع صواعق | C9: Anti Strom | D9: No. | E9: =[3]Summary!E8 -> 12.5 | F9: =[3]Summary!F8 -> 0 | G9: =F9*E9 -> 0 | H9: other
A10: 6 | B10: اوتوماتيك سخان برادفورد | C10: Automatic Boilar (Brad Ford) 200v-240v | D10: No. | E10: =[3]Summary!E9 -> 30 | F10: =[3]Summary!F9 -> 0 | G10: =F10*E10 -> 0 | H10: other
A11: 7 | B11: افوميتر | C11: Avometer | D11: No. | E11: =[3]Summary!E10 -> 42 | F11: =[3]Summary!F10 -> 0 | G11: =F11*E11 -> 0 | H11: other
A12: 8 | B12: هيتر سخان عارضة | C12: Bain Marie Heater | D12: No. | E12: =[3]Summary!E11 -> 40 | F12: =[3]Summary!F11 -> 0 | G12: =F12*E12 -> 0 | H12: Heaters
A13: 9 | B13: قاعدة كلفنايز لتثبيت عازل بازبار2*6*2 سمك2ملم | C13: Base Base Galvanis For Isolated Bus-Bar 2*6*2 | D13: No. | E13: =[3]Summary!E12 -> 1.375 | F13: =[3]Summary!F12 -> 0 | G13: =F13*E13 -> 0 | H13: Bus Bar
A14: 10 | B14: قاعدة تثبيت تراي كيبل ارضي 16سم | C14: Base Cable Trunking Ground 16cm Iron | D14: No. | E14: =[3]Summary!E13 -> 1.5 | F14: =[3]Summary!F13 -> 0 | G14: =F14*E14 -> 0 | H14: Cable tray
A15: 11 | B15: قاعدة تثبيت تراي كيبل ارضي 10سم | C15: Base Cable Trunking ground Iron 10cm | D15: No. | E15: =[3]Summary!E14 -> 1 | F15: =[3]Summary!F14 -> 6 | G15: =F15*E15 -> 6 | H15: Cable tray
A16: 12 | B16: قاعدة تثبيت تراي كيبل جداري 10سم | C16: Base Cable Trunking Wall 10cm | D16: No. | E16: =[3]Summary!E15 -> 1.25 | F16: =[3]Summary!F15 -> 49 | G16: =F16*E16 -> 61.25 | H16: Cable tray
... A373: 369 | B373: جنكشن بوكس ثلاثي 25ملم | C373: Junction Box tripple 25mm | D373: No. | E373: =[3]Summary!E372 -> 0.4 | F373: =[3]Summary!F372 -> 222 | G373: =F373*E373 -> 88.8 | H373: junction Box
A374: 370 | C374: LDNIO SC3604 10A Power Strip 3 Socket 6 USB | D374: No. | E374: =[3]Summary!E373 -> 6.75 | F374: =[3]Summary!F373 -> 0 | G374: =F374*E374 -> 0 | H374: Socket
A375: 371 | B375: سيار كهربائي 6يو اي بي 3بلك لدنيو | C375: LED levant 2835/240 M ( 6M) 24V 18 W | D375: Roll. | E375: =[3]Summary!E374 -> 190 | F375: =[3]Summary!F374 -> 0 | G375: =F375*E375 -> 0 | H375: Lighting
A376: 372 | B376: منظم قولتية | C376: Voltage Regulator R250 | D376: No. | E376: =[3]Summary!E375 -> 400 | F376: =[3]Summary!F375 -> 0 | G376: =F376*E376 -> 0 | H376: other
A377: 373 | B377: بلاجتكور 400واط | C377: projector 400W | D377: No. | E377: =[3]Summary!E376 -> 95 | F377: =[3]Summary!F376 -> 0 | G377: =F377*E377 -> 0 | H377: Lighting
A378: 374 | B378: بلاجكتور 150 واط | C378: projector 150W | D378: No. | E378: =[3]Summary!E377 -> 60 | F378: =[3]Summary!F377 -> 1 | G378: =F378*E378 -> 60 | H378: Lighting
A379: 375 | B379: لايت دائري 15 واط | C379: Light Circular 15W | D379: No. | E379: =[3]Summary!E378 -> 3.25 | F379: =[3]Summary!F378 -> 0 | G379: =F379*E379 -> 0 | H379: Lighting
A380: 376 | B380: لايت دائري 20 واط | C380: Light Circular 20W | D380: No. | E380: =[3]Summary!E379 -> 6 | F380: =[3]Summary!F379 -> 42 | G380: =F380*E380 -> 252 | H380: Lighting
A381: 377 | B381: لايت دائري 22واط بي جي | C381: Light Circular 22W BG | D381: No. | E381: =[3]Summary!E380 -> 6.5 | F381: =[3]Summary!F380 -> 0 | G381: =F381*E381 -> 0 | H381: Lighting
A382: 378 | B382: لايت دائري 24 واط روز | C382: Light Circular 24W Rozh | D382: No. | E382: =[3]Summary!E381 -> 3.5 | F382: =[3]Summary!F381 -> 1 | G382: =F382*E382 -> 3.5 | H382: Lighting
A383: 379 | B383: لايت تعليق كلاسيك خشب مع حبل | C383: Light Classic Wood Suspension With Rope | D383: No. | E383: =[3]Summary!E382 -> 60 | F383: =[3]Summary!F382 -> 0 | G383: =F383*E383 -> 0 | H383: Lighting
A384: 380 | B384: لايت ليد كلوب 5 واط | C384: Light Led 5W Lamp | D384: No. | E384: =[3]Summary!E383 -> 1.15 | F384: =[3]Summary!F383 -> 0 | G384: =F384*E384 -> 0 | H384: Lighting
A385: 381 | B385: لايت ليد بيضوي 15 واط سبارك | C385: Light LED Oval 15W Spark | D385: No. | E385: =[3]Summary!E384 -> 3.75 | F385: =[3]Summary!F384 -> 0 | G385: =F385*E385 -> 0 | H385: Lighting
A386: 382 | B386: ايت ليد بيضوي 15 واط فومسي | C386: Light Oval 15W Fomsi | D386: No. | E386: =[3]Summary!E385 -> 3.25 | F386: =[3]Summary!F385 -> 4 | G386: =F386*E386 -> 13 | H386: Lighting
... A795: 791 | B795: حساس دخان باكيت ابيض | C795: Smoke Detector single station everday sd728 series | D795: EA | E795: =[3]Summary!E794 -> 0 | F795: =[3]Summary!F794 -> 57 | G795: =F795*E795 -> 0 | H795: Detectors
A796: 792 | B796: كونكتر ثلاثي WAGO | C796: Connector Tripple WAGO | D796: EA | E796: =[3]Summary!E795 -> 0.4 | F796: =[3]Summary!F795 -> 0 | G796: =F796*E796 -> 0
A797: 793 | B797: كونكتر خماسي WAGO | C797: Connector five WAGO 221-0415 | D797: EA | E797: =[3]Summary!E796 -> 0.6 | F797: =[3]Summary!F796 -> 4 | G797: =F797*E797 -> 2.4
A798: 794 | B798: جوزة شنادير 2 بول ايرثلكج 32 امبير | C798: RCBO 2P 32A 50° Schneider | D798: EA | E798: =[3]Summary!E797 -> 28 | F798: =[3]Summary!F797 -> 5 | G798: =F798*E798 -> 140
A799: 795 | B799: نيون لد 4قدم روز | C799: Neon LED 4Foot Rozh | D799: EA | E799: =[3]Summary!E798 -> 1.2 | F799: =[3]Summary!F798 -> 4 | G799: =F799*E799 -> 4.8
A801: Total | F801: =SUM(F5:F799) -> 72223.435 | G801: =SUM(G5:G799) -> 255586.77

Sheet Plumbing Store
A2: =TODAY() -> 46123
A3: مخزن صحيات / Plumbing Store
A4: ت | B4: اسم المادة | C4: Subject Name | D4: الوحدة Unit | E4: Rate Per Unit القيمة لكل وحدة | F4: الكمية Qty | G4: Total Unit المجموع | H4: Type
A5: 1 | B5: توصالة كاز حديد 1"*3/4 | C5: Adapter Nipple 1" * 3/4 Gazoil | D5: EA | E5: =[4]Summary!E4 -> 3 | F5: =[4]Summary!F4 -> 0 | G5: =E5*F5 -> 0 | H5: Gaz. Fittings
A6: 2 | B6: توصالة كاز حديد 1"*3/4 | C6: Adapter Nipple For pvc welding machine | D6: EA | E6: =[4]Summary!E5 -> 1.7 | F6: =[4]Summary!F5 -> 0 | G6: =E6*F6 -> 0 | H6: Pvc Fittings
A7: 3 | B7: ادابتر شور 1/2* 25ملم | C7: Adapter shower PPR 1/2*25 | D7: EA | E7: =[4]Summary!E6 -> 2.6 | F7: =[4]Summary!F6 -> 0 | G7: =E7*F7 -> 0 | H7: PPR Fittings
A8: 4 | B8: ادبتر 1/2*3/4 PPR حراري | C8: Adpter PPR 3/4*1/2 Thermal | D8: EA | E8: =[4]Summary!E7 -> 0.15 | F8: =[4]Summary!F7 -> 0 | G8: =E8*F8 -> 0 | H8: PPR Fittings
A9: 5 | B9: ادابتر UPVC 90*110 | C9: Adpter UPVC 90*110 | D9: EA | E9: =[4]Summary!E8 -> 20 | F9: =[4]Summary!F8 -> 0 | G9: =E9*F9 -> 0 | H9: Upvc Fittings
A10: 6 | B10: ادبتر هواء مع زبانة صوندة 1/4 | C10: Air Adpter With Nipple Hose Air 1/4 | D10: EA | E10: =[4]Summary!E9 -> 10.135 | F10: =[4]Summary!F9 -> 0 | G10: =E10*F10 -> 0 | H10: Gal. Fittings
A11: 7 | B11: قبغ تنفيس 2.5" | C11: Air Cap 2.5" PVC | D11: EA | E11: =[4]Summary!E10 -> 1 | F11: =[4]Summary!F10 -> 0 | G11: =E11*F11 -> 0 | H11: Pvc Fittings
A12: 8 | B12: قبغ تنفيس 4" | C12: Air Cap 4" PVC | D12: EA | E12: =[4]Summary!E11 -> 2 | F12: =[4]Summary!F11 -> 1 | G12: =E12*F12 -> 2 | H12: Pvc Fittings
A13: 9 | B13: قبغ تنفيس 1.5" | C13: Air Cap 1.5" PVC | D13: EA | E13: =[4]Summary!E12 -> 0.35 | F13: =[4]Summary!F12 -> 254 | G13: =E13*F13 -> 88.9 | H13: Pvc Fittings
A14: 10 | B14: كب 1.5" | C14: Cap 1.5" UPVC Gray | D14: EA | E14: =[4]Summary!E13 -> 1.5 | F14: =[4]Summary!F13 -> 11 | G14: =E14*F14 -> 16.5 | H14: Upvc Fittings
A15: 11 | B15: كب 4" | C15: Cap 4" UPVC Gray | D15: EA | E15: =[4]Summary!E14 -> 2.75 | F15: =[4]Summary!F14 -> 5 | G15: =E15*F15 -> 13.75 | H15: Upvc Fittings
A16: 12 | B16: كب 2" | C16: Cap 2" UPVC Gray | D16: EA | E16: =[4]Summary!E15 -> 2 | F16: =[4]Summary!F15 -> 16 | G16: =E16*F16 -> 32 | H16: Upvc Fittings
... A665: 661 | B665: تقسيم تي 1.25" زراعي | C665: Split T 1.25" hdpe agriculture | D665: EA | E665: =[4]Summary!E664 -> 22 | F665: =[4]Summary!F664 -> 0 | G665: =E665*F665 -> 0 | H665: Agriculture Fittings
A666: 662 | B666: تقسيم تي 1.5" زراعي | C666: Split T 1.5" hdpe agriculture | D666: EA | E666: 0 | F666: =[4]Summary!F665 -> 1 | G666: =E666*F666 -> 0 | H666: Agriculture Fittings
A667: 663 | B667: PPR 1.25" T تقسيم | C667: Split T 1.25" PPR | D667: EA | E667: =[4]Summary!E666 -> 0.51 | F667: =[4]Summary!F666 -> 18 | G667: =E667*F667 -> 9.18 | H667: PPR Fittings
A668: 664 | B668: PPR 1.5" T تقسيم | C668: Split T 1.5" PPR | D668: EA | E668: =[4]Summary!E667 -> 0.95 | F668: =[4]Summary!F667 -> 112 | G668: =E668*F668 -> 106.4 | H668: PPR Fittings
A669: 665 | B669: PPR 2 * 3/4" T تقسيم | C669: Split T 2" * 3/4" PPR | D669: EA | E669: =[4]Summary!E668 -> 2.12 | F669: =[4]Summary!F668 -> 30 | G669: =E669*F669 -> 63.6 | H669: PPR Fittings
A670: 666 | B670: تقسيم تي 2" زراعي | C670: Split T 2" hdpe agriculture | D670: EA | E670: =[4]Summary!E669 -> 6.8 | F670: =[4]Summary!F669 -> 2 | G670: =E670*F670 -> 13.6 | H670: Agriculture Fittings
A671: 667 | B671: تقسيم تي حديد "2 | C671: Split T 2" Galvanis | D671: EA | E671: =[4]Summary!E670 -> 3.25 | F671: =[4]Summary!F670 -> 0 | G671: =E671*F671 -> 0 | H671: Gal. Fittings
A672: 668 | B672: PPR 2" T تقسيم | C672: Split T 2" PPR | D672: EA | E672: =[4]Summary!E671 -> 2.2 | F672: =[4]Summary!F671 -> 100 | G672: =E672*F672 -> 220 | H672: PPR Fittings
A673: 669 | B673: تقسيم تي"2 UPVC رصاصي | C673: Split T 2" UPVC Gray | D673: EA | E673: =[4]Summary!E672 -> 0 | F673: =[4]Summary!F672 -> 0 | G673: =E673*F673 -> 0 | H673: Upvc Fittings
A674: 670 | B674: تقسيم تي"2 * 1" UPVC رصاصي | C674: Split T 2"1" UPVC Gray | D674: EA | E674: =[4]Summary!E673 -> 0 | F674: =[4]Summary!F673 -> 6 | G674: =E674*F674 -> 0 | H674: Upvc Fittings
A675: 671 | B675: تقسيم تي 1.5" UPVC رصاصي | C675: Split T 1.5" UPVC Gray | D675: EA | E675: =[4]Summary!E674 -> 0 | F675: =[4]Summary!F674 -> 2 | G675: =E675*F675 -> 0 | H675: Upvc Fittings
A676: 672 | B676: تقسيم تي 1.5" UPVC رصاصي | C676: Split T 2.5" Quarter UPVC Gray | D676: EA | E676: =[4]Summary!E675 -> 0 | F676: =[4]Summary!F675 -> 0 | G676: =E676*F676 -> 0 | H676: Upvc Fittings
A677: 673 | B677: تقسيم تي 2" UPVC رصاصي | C677: Split T 2" Quarter UPVC Gray | D677: EA | E677: =[4]Summary!E676 -> 0 | F677: =[4]Summary!F676 -> 6 | G677: =E677*F677 -> 0 | H677: Upvc Fittings
A678: 674 | B678: تقسيم تي 1/2" UPVC رصاصي | C678: Split T 1/2" UPVC Gray | D678: EA | E678: =[4]Summary!E677 -> 0 | F678: =[4]Summary!F677 -> 1 | G678: =E678*F678 -> 0 | H678: Upvc Fittings
... A823: 819 | B823: بوشة مصغرة 1.5"*1.25" كلفنايز | C823: Reducer Bushing 1.5"*1.25" Galvanis | D823: EA | E823: =[4]Summary!E822 -> 2 | F823: =[4]Summary!F822 -> 5 | G823: =E823*F823 -> 10 | H823: Gal. Fittings
A824: 820 | B824: توصالة 8" UPVC | C824: Coupling 8" UPVC | D824: EA | E824: =[4]Summary!E823 -> 14 | F824: =[4]Summary!F823 -> 5 | G824: =E824*F824 -> 70
A825: 821 | B825: بوشة مصغرة 1.5"*1.25" كلفنايز | C825: Pipe 8" UPVC | D825: EA | E825: =[4]Summary!E824 -> 28 | F825: =[4]Summary!F824 -> 1 | G825: =E825*F825 -> 28
A826: 822 | B826: قفيص حديد بوري"8 دائري | C826: Pipe Circular Iron Clamp 8" | D826: EA | E826: =[4]Summary!E825 -> 2.5 | F826: =[4]Summary!F825 -> 15 | G826: =E826*F826 -> 37.5
A828: Total | F828: =SUM(F5:F826) -> 22142.703 | G828: =SUM(G5:G826) -> 43779.062

Sheet PVC Store
A2: =TODAY() -> 46123
A3: PVC مخزن
A4: ت | B4: اسم المادة | C4: Subject Name | D4: الوحدة Unit | E4: Rate Total | F4: الكمية Qty | G4: total | H4: Remark
A5: 1 | B5: لامبيري شمباني المنيوم | C5: Aluminium champagne color Lambert old | D5: EA. | E5: =[5]Summary!E4 -> 0 | F5: =[5]Summary!F4 -> 15 | G5: =E5*F5 -> 0
A6: 2 | B6: لامبيري ابيض المنيوم | C6: aluminium White Lambert | D6: EA. | E6: =[5]Summary!E5 -> 10.9476 | F6: =[5]Summary!F5 -> 24 | G6: =E6*F6 -> 262.7424
A7: 3 | B7: لقمة المنيوم سلفر 6م | C7: Aluminium Holder Silver 6m | D7: EA. | E7: =[5]Summary!E6 -> 15 | F7: =[5]Summary!F6 -> 10.41 | G7: =E7*F7 -> 156.15
A8: 4 | B8: سركي(قفل) باب المنيوم | C8: Aluminium Latch Door lock | D8: EA. | E8: =[5]Summary!E7 -> 1.95 | F8: =[5]Summary!F7 -> 0 | G8: =E8*F8 -> 0
A9: 5 | B9: زاوية بلاستيك مانع ذباب ابيض | C9: Angle (Fly Blocker) Plastic | D9: EA. | E9: =[5]Summary!E8 -> 0.07 | F9: =[5]Summary!F8 -> 90 | G9: =E9*F9 -> 6.3
A10: 6 | B10: زاوية ديكور PVC ابيض 3.66سم | C10: Angle PVC Dicoration white 3.60cm | D10: EA. | E10: =[5]Summary!E9 -> 0 | F10: =[5]Summary!F9 -> 34 | G10: =E10*F10 -> 0
A11: 7 | B11: نرمادو دسكو كبيرة | C11: Big Hinge Disco old | D11: EA. | E11: =[5]Summary!E10 -> 0.45 | F11: =[5]Summary!F10 -> 2 | G11: =E11*F11 -> 0.9
A12: 8 | B12: لاستيك اسود ربل 100متر | C12: Black Lastic 100m MAKEPLAST | D12: Roll | E12: =[5]Summary!E11 -> 8 | F12: =[5]Summary!F11 -> 1.55 | G12: =E12*F12 -> 12.4
A13: 9 | B13: زاوية PVC جوزي 5 * 10 | C13: Brown Angle PVC 5 * 10 | D13: EA. | E13: =[5]Summary!E12 -> 19 | F13: =[5]Summary!F12 -> 35 | G13: =E13*F13 -> 665
A14: 10 | B14: فرشاة اسفل باب | C14: Brush Down Door 1m | D14: EA. | E14: =[5]Summary!E13 -> 1.5 | F14: =[5]Summary!F13 -> 93 | G14: =E14*F14 -> 139.5
A15: 11 | B15: جوزة باب PVC والمنيوم | C15: Cylinder Lock PVC&Aluminium Door | D15: EA. | E15: =[5]Summary!E14 -> 3 | F15: =[5]Summary!F14 -> 47 | G15: =E15*F15 -> 141
A16: 12 | B16: جوزة باب المنيوم WC | C16: Cylinder Lock Aluminium Door W.C | D16: EA. | E16: =[5]Summary!E15 -> 3 | F16: =[5]Summary!F15 -> 14 | G16: =E16*F16 -> 42
... A98: 94 | B98: باب خشب سنكل 90*203 | C98: Single Door Wood 90*203cm | D98: EA | E98: =[5]Summary!E97 -> 100 | F98: =[5]Summary!F97 -> 12 | G98: =E98*F98 -> 1200
A99: 95 | B99: لوفر باب المنيوم 100*160 سم | C99: Louvers Aluminum100*160cm Window | D99: EA. | E99: =[5]Summary!E98 -> 155 | F99: =[5]Summary!F98 -> 0 | G99: =F99*E99 -> 0
A100: 96 | B100: لوفر باب المنيوم 20*15 سم | C100: Louvers Aluminum 20*15cm | D100: EA. | E100: =[5]Summary!E99 -> 29 | F100: =[5]Summary!F99 -> 29 | G100: =F100*E100 -> 841
A101: 97 | B101: لوفر باب المنيوم 30*60 سم | C101: Louvers Aluminum 30*60cm | D101: EA. | E101: =[5]Summary!E100 -> 10 | F101: =[5]Summary!F100 -> 0 | G101: =F101*E101 -> 0
A102: 98 | B102: لوفر باب المنيوم 35*25 سم | C102: Louvers Aluminum 35*25cm | D102: EA. | E102: =[5]Summary!E101 -> 45 | F102: =[5]Summary!F101 -> 0 | G102: =F102*E102 -> 0
A103: 99 | B103: لوفر باب المنيوم 45*85 سم | C103: Louvers Aluminum 45*85cm | D103: EA. | E103: =[5]Summary!E102 -> 60 | F103: =[5]Summary!F102 -> 0 | G103: =F103*E103 -> 0
A104: 100 | B104: لوفر باب المنيوم 50*50 سم | C104: Louvers Aluminum 50*50cm Window | D104: EA. | E104: =[5]Summary!E103 -> 60 | F104: =[5]Summary!F103 -> 0 | G104: =F104*E104 -> 0
A105: 101 | B105: لوفر باب المنيوم 50*60 سم | C105: Louvers Aluminum 50*60cm Window | D105: EA. | E105: =[5]Summary!E104 -> 60 | F105: =[5]Summary!F104 -> 0 | G105: =F105*E105 -> 0
A106: 102 | B106: لوفر باب المنيوم 55*25 سم | C106: Louvers Aluminum 55*25cm | D106: EA. | E106: =[5]Summary!E105 -> 50 | F106: =[5]Summary!F105 -> 0 | G106: =F106*E106 -> 0
A107: 103 | B107: لقمة المنيوم سلفر 6متر تجميع لزد شباك المنيوم | C107: Aluminium Holder Silver 6m window | D107: EA. | E107: =[5]Summary!E106 -> 24 | F107: =[5]Summary!F106 -> 0 | G107: =F107*E107 -> 0
A108: 104 | B108: تي شباك pvc | C108: T white window PVC | D108: EA | E108: =[5]Summary!E107 -> 10.95 | F108: =[5]Summary!F107 -> 89 | G108: =E108*F108 -> 974.55
A109: 105 | B109: زاوية ابيض بلاستك 3 * 3 سم | C109: White Angle PVC 3cm * 3cm 3m | D109: EA. | E109: =[5]Summary!E108 -> 1.5 | F109: =[5]Summary!F108 -> 0 | G109: =F109*E109 -> 0
A110: 106 | B110: ربل اسود لماسكة دبل المنيوم | C110: Black Rubber for Aluminium catch double 50mt | D110: Roll | E110: =[5]Summary!E109 -> 0.25 | F110: =[5]Summary!F109 -> 152 | G110: =E110*F110 -> 38
A113: Total | F113: =SUM(F5:F110) -> 4604.996 | G113: =SUM(G5:G110) -> 12423.709

Sheet Paint Store
A2: =TODAY() -> 46123
A3: مخزن اصباغ / Paint store
A4: ت | B4: اسم المادة | C4: Subject Name | D4: الوحدة Unit | E4: Rate Per Unit القيمة لكل وحدة | F4: الكمية .Qty | G4: total المجموع | H4: Remark ملاحظة
A5: 1 | B5: لاصق فاينل | C5: Adhesive Vinyl | D5: Pail. | E5: =[6]Summary!E4 -> 26.41 | F5: =[6]Summary!F4 -> 187.5 | G5: =F5*E5 -> 4951.875
A6: 2 | B6: لاصق فاينل ايران | C6: ='[6]Adhesive Vinyl Irani 3kg'!$K$3 -> Adhesive Vinyl Irani 3kg | D6: Pail. | E6: =[6]Summary!E5 -> 10 | F6: =[6]Summary!F5 -> 2 | G6: =F6*E6 -> 20
A7: 3 | B7: صبغ اسود ليرة | C7: Black Panit Lira | D7: Pail. | E7: =[6]Summary!E6 -> 9 | F7: =[6]Summary!F6 -> 2.85 | G7: =F7*E7 -> 25.65
A8: 4 | B8: سليكون اسود وورث | C8: Black Silicon Wurth 300ml | D8: No. | E8: =[6]Summary!E7 -> 2.85 | F8: =[6]Summary!F7 -> 7 | G8: =F8*E8 -> 19.95
A9: 5 | B9: صبغ بخاخ اسود | C9: Black Spray Paint | D9: No. | E9: =[6]Summary!E8 -> 0.4584 | F9: =[6]Summary!F8 -> 15 | G9: =F9*E9 -> 6.876
A10: 6 | B10: صبغ بخاخ ازرق | C10: Blue Spray Paint Polinice | D10: No. | E10: =[6]Summary!E9 -> 0.521 | F10: =[6]Summary!F9 -> 80 | G10: =F10*E10 -> 41.68
A11: 7 | B11: ثنر بطل 2.84لتر | C11: Bottle Thinner 2.84L | D11: Bott. | E11: =[6]Summary!E10 -> 1.73 | F11: =[6]Summary!F10 -> 0 | G11: =F11*E11 -> 0
A12: 8 | B12: سليكون شفاف | C12: clear silicon | D12: No. | E12: =[6]Summary!E11 -> 1.25 | F12: =[6]Summary!F11 -> 0 | G12: =F12*E12 -> 0
A13: 9 | B13: ايبوكسي | C13: Epoxy Injectable mortar HIT-HY | D13: No. | E13: =[6]Summary!E12 -> 33 | F13: =[6]Summary!F12 -> 0 | G13: =F13*E13 -> 0
A14: 10 | B14: ايبوكسي | C14: Epoxy Injectable mortar HIT-RE | D14: No. | E14: =[6]Summary!E13 -> 32 | F14: =[6]Summary!F13 -> 0 | G14: =F14*E14 -> 0
A15: 11 | B15: ايبوكسي | C15: Epoxy Soudal 300ml P300.ST | D15: No. | E15: =[6]Summary!E14 -> 5 | F15: =[6]Summary!F14 -> 3 | G15: =F15*E15 -> 15
A16: 12 | B16: سيكوتين بخاخ | C16: fast adhesive | D16: No. | E16: =[6]Summary!E15 -> 1.83 | F16: =[6]Summary!F15 -> 18 | G16: =F16*E16 -> 32.94
A17: 13 | B17: لاصق قوام بخاخ | C17: fast spray QWAM | D17: No. | E17: =[6]Summary!E16 -> 1 | F17: =[6]Summary!F16 -> 1 | G17: =F17*E17 -> 1
A18: 14 | B18: فوم وورث | C18: Foam Wurth 750ml | D18: No. | E18: =[6]Summary!E17 -> 6.5 | F18: =[6]Summary!F17 -> 0 | G18: =F18*E18 -> 0
... A25: 21 | B25: سليكون كيتر شفاف | C25: Gutter Clear Silicon | D25: No. | E25: =[6]Summary!E24 -> 3.11 | F25: =[6]Summary!F24 -> 13 | G25: =F25*E25 -> 40.43
A26: 22 | B26: ='[6]Gypsum Board Smoothing Sponge'!$N$4 -> اسفنج تنعيم جبسم بورد | C26: Gypsum Board Smoothing Sponge | D26: No. | E26: =[6]Summary!E25 -> 0.5 | F26: =[6]Summary!F25 -> 1 | G26: =F26*E26 -> 0.5
A27: 23 | B27: جوتيك ستايل | C27: Jotuk Style fabric | D27: Rol. | E27: =[6]Summary!E26 -> 95 | F27: =[6]Summary!F26 -> 0 | G27: =F27*E27 -> 0
A28: 24 | B28: صبغ جوتن | C28: Jotun Matt Base Paint 16.2L | D28: Pail. | E28: =[6]Summary!E27 -> 95 | F28: =[6]Summary!F27 -> 0 | G28: =F28*E28 -> 0
A29: 25 | B29: صبغ جوتن | C29: Jotun Paint 1931 18Lt | D29: Pail. | E29: =[6]Summary!E28 -> 72 | F29: =[6]Summary!F28 -> 0 | G29: =F29*E29 -> 0
A30: 26 | B30: صبغ جوتن | C30: Jotun Paint 3.6L 10342 | D30: Pail. | E30: =[6]Summary!E29 -> 19 | F30: =[6]Summary!F29 -> 0 | G30: =F30*E30 -> 0
A31: 27 | B31: صبغ جوتن | C31: Jotun Paint 3.6l 8395 | D31: Pail. | E31: =[6]Summary!E30 -> 19 | F31: =[6]Summary!F30 -> 0 | G31: =F31*E31 -> 0
A32: 28 | B32: صبغ جوتن | C32: Jotun Paint 3.6L 9004 | D32: Pail. | E32: =[6]Summary!E31 -> 24 | F32: =[6]Summary!F31 -> 0 | G32: =F32*E32 -> 0
A33: 29 | B33: صبغ جوتن | C33: Jotun Paint External 18Lt | D33: Pail. | E33: =[6]Summary!E32 -> 60 | F33: =[6]Summary!F32 -> 0 | G33: =F33*E33 -> 0
A34: 30 | B34: صبغ جوتن | C34: JOTUN Paint Gray 7035 3.6L | D34: Pail. | E34: =[6]Summary!E33 -> 23 | F34: =[6]Summary!F33 -> 0 | G34: =F34*E34 -> 0
A35: 31 | B35: صبغ جوتن | C35: Jotun Paint Primer Alkali DU-20 | D35: Pail. | E35: =[6]Summary!E34 -> 60 | F35: =[6]Summary!F34 -> 0 | G35: =F35*E35 -> 0
A36: 32 | B36: صبغ جوتن خارجي 3.6لتر 8395 | C36: Jotun Paint Tex Ultra Base A 3. | D36: Pail. | E36: =[6]Summary!E35 -> 30 | F36: =[6]Summary!F35 -> 0 | G36: =F36*E36 -> 0
A37: 33 | B37: صبغ جوتن 3.6لتر | C37: Jotun Primer Paint 3.6l | D37: Pail. | E37: =[6]Summary!E36 -> 23 | F37: =[6]Summary!F36 -> 6.5 | G37: =F37*E37 -> 149.5
A38: 34 | B38: قلاكيم | C38: Kalekim 1954 25k | D38: bag. | E38: =[6]Summary!E37 -> 14 | F38: =[6]Summary!F37 -> 0 | G38: =F38*E38 -> 0
... A40: 36 | B40: صبغ دهني برتقالي | C40: orange paint dewilux | D40: Pail. | E40: =[6]Summary!E39 -> 27.75 | F40: =[6]Summary!F39 -> 0.25 | G40: =F40*E40 -> 6.9375
A41: 37 | B41: ='[6]Original Wood Glue 3.78lt'!$L$4 -> صمغ خشب 3.78لتر | C41: Original Wood Glue 3.78lt | D41: Pail. | E41: =[6]Summary!E40 -> 35 | F41: =[6]Summary!F40 -> 0 | G41: =F41*E41 -> 0
A42: 38 | B42: صبغ بيتك اسود برايمر | C42: Paint Black Betek Praimer 2.5L | D42: Pail. | E42: =[6]Summary!E41 -> 9.55 | F42: =[6]Summary!F41 -> 2.938 | G42: =F42*E42 -> 28.0579
A43: 39 | B43: فرجة صبغ 1" | C43: Paint Brush 1" | D43: No. | E43: =[6]Summary!E42 -> 0.1917 | F43: =[6]Summary!F42 -> 54 | G43: =F43*E43 -> 10.3518
A44: 40 | B44: فرجة صبغ 2" | C44: Paint Brush 2" | D44: No. | E44: =[6]Summary!E43 -> 0.54 | F44: =[6]Summary!F43 -> 9 | G44: =F44*E44 -> 4.86
A45: 41 | B45: فرجة صبغ خشب 1" | C45: Paint Brush Wood 1" ACE | D45: No. | E45: =[6]Summary!E44 -> 0.17 | F45: =[6]Summary!F44 -> 0 | G45: =F45*E45 -> 0
A46: 42 | B46: فرجة صبغ خشب 1.5" | C46: Paint Brush Wood 1.5" ACE | D46: No. | E46: =[6]Summary!E45 -> 1.034 | F46: =[6]Summary!F45 -> 0 | G46: =F46*E46 -> 0
A47: 43 | B47: فرجة صبغ خشب 2" | C47: Paint Brush Wood 2" ACE | D47: No. | E47: =[6]Summary!E46 -> 1.54 | F47: =[6]Summary!F46 -> 0 | G47: =F47*E47 -> 0
A48: 44 | B48: فرجة صبغ خشب 2.5" | C48: Paint Brush Wood 2.5" ACE | D48: No. | E48: =[6]Summary!E47 -> 2.05 | F48: =[6]Summary!F47 -> 0 | G48: =F48*E48 -> 0
...

Sheet AC Unit Store
A2: =TODAY() -> 46123
A3: مخزن سبالت / AC Unit store
A4: ت | B4: اسم المادة | C4: Subject Name | D4: الوحدة Unit | E4: Rate Per Unit القيمة لكل وحدة | F4: الكمية .Qty | G4: total المجموع | H4: Remark ملاحظة
A5: 1 | B5: كيس نايلون كفر للقطع الداخلية | C5: AC cover Nylon inside | D5: No. | E5: =[7]Summary!E4 -> 6 | F5: =[7]Summary!F4 -> 2 | G5: =F5*E5 -> 12
A6: 2 | B6: بردة هواء 22*22*90 | C6: Air Curtain 22*22*90 | D6: No. | E6: =[7]Summary!E5 -> 0 | F6: =[7]Summary!F5 -> 1 | G6: =F6*E6 -> 0
A7: 3 | B7: بردة هواء 26*24.5*185 | C7: Air Curtain 26*24.5*185 | D7: No. | E7: =[7]Summary!E6 -> 0 | F7: =[7]Summary!F6 -> 6 | G7: =F7*E7 -> 0
A8: 4 | B8: بردة هواء 27.5*22.5*156 | C8: Air Curtain 27.5*22.5*165 | D8: No. | E8: =[7]Summary!E7 -> 0 | F8: =[7]Summary!F7 -> 3 | G8: =F8*E8 -> 0
A9: 5 | B9: مبردة هوائية كري FM-1.251k | C9: Air Curtain Gree 120cm | D9: No. | E9: =[7]Summary!E8 -> 6 | F9: =[7]Summary!F8 -> 2 | G9: =F9*E9 -> 12
A10: 6 | B10: قاعدة تعليق سبالت خارجية L | C10: Base OutSide AC Siplet | D10: No. | E10: =[7]Summary!E9 -> 8 | F10: =[7]Summary!F9 -> 9 | G10: =F10*E10 -> 72
A11: 7 | B11: قاعدة ريموت كنترول سبالت كري | C11: Base Remote Control Split AC | D11: No. | E11: =[7]Summary!E10 -> 0.714 | F11: =[7]Summary!F10 -> 0 | G11: =F11*E11 -> 0
A12: 8 | B12: قنينة سبلت منظف داستي | C12: Bottle Split Cleaner dasty | D12: No. | E12: =[7]Summary!E11 -> 4.25 | F12: =[7]Summary!F11 -> 3 | G12: =F12*E12 -> 12.75
A13: 9 | B13: عواجة بوري سبلت 1/2 | C13: Carvuture Pipe Split AC 1/2 | D13: No. | E13: =[7]Summary!E12 -> 20.8 | F13: =[7]Summary!F12 -> 1 | G13: =F13*E13 -> 20.8
A14: 10 | B14: عواجة بوري سبلت 3/4 | C14: Carvuture Pipe Split AC 3/4 | D14: No. | E14: =[7]Summary!E13 -> 20.8 | F14: =[7]Summary!F13 -> 1 | G14: =F14*E14 -> 20.8
A15: 11 | B15: عواجة بوري سبلت 3/8 | C15: Carvuture Pipe Split AC 3/8 | D15: No. | E15: =[7]Summary!E14 -> 20.8 | F15: =[7]Summary!F14 -> 1 | G15: =F15*E15 -> 20.8
A16: 12 | B16: عواجة بوري سبلت 5/8 | C16: Carvuture Pipe Split AC 5/8 | D16: No. | E16: =[7]Summary!E15 -> 20 | F16: =[7]Summary!F15 -> 1 | G16: =F16*E16 -> 20
... A73: 69 | B73: قاعدة سبلت قطعة خارجية 200كيلو | C73: Air Conditioner Bracket | D73: No. | E73: =[7]Summary!E72 -> 6.25 | F73: =[7]Summary!F72 -> 5 | G73: =F73*E73 -> 31.25
A75: Total | F75: =SUM(F5:F73) -> 5117 | G75: =SUM(G5:G73) -> 23262.531

Sheet Furniture Store
A2: =TODAY() -> 46123
A3: مخزن اثاث /Furniture Store
A4: ت | B4: اسم المادة | C4: Subject Name | D4: الوحدة Unit | E4: Rate Per Unit القيمة لكل وحدة | F4: الكمية .Qty | G4: total المجموع | H4: Remark ملاحظة
A5: 1 | B5: سرير طابق واحد | C5: Iron Bed 1 2m | D5: EA | E5: =[8]summary!E4 -> 293 | F5: =[8]summary!F4 -> 2 | G5: =E5*F5 -> 586
A6: 2 | B6: سرير طابقين | C6: Iron Double Bed 1 2m | D6: EA | E6: =[8]summary!E5 -> 142 | F6: =[8]summary!F5 -> 2 | G6: =E6*F6 -> 284
A7: 3 | B7: جرجف عادي | C7: Normal Bedding Sheets | D7: EA | E7: =[8]summary!E6 -> 5.34 | F7: =[8]summary!F6 -> 2 | G7: =E7*F7 -> 10.68
A8: 4 | B8: مخدة 700 غرام | C8: Pillow 700g | D8: EA | E8: =[8]summary!E7 -> 5 | F8: =[8]summary!F7 -> 0 | G8: =E8*F8 -> 0
A9: 5 | B9: قاعدة تلفزيون جداري | C9: TV Wall Mounts Sonic | D9: EA | E9: =[8]summary!E8 -> 19 | F9: =[8]summary!F8 -> 21 | G9: =E9*F9 -> 399
A10: 6 | B10: سلم فايبركلاس 7باية A | C10: Step Ladder Fiberglass 7step A | D10: EA | E10: =[8]summary!E9 -> 75 | F10: =[8]summary!F9 -> 2 | G10: =E10*F10 -> 150
A11: 7 | B11: سلم فايبركلاس سلايت حبل 11م | C11: Step Ladder Slide 11mt Powerline | D11: EA | E11: =[8]summary!E10 -> 250 | F11: =[8]summary!F10 -> 1 | G11: =E11*F11 -> 250
A12: 8 | B12: سلم فايبركلاس 6باية A بورلاين احمر | C12: Step Ladder Fiberglass 5step A | D12: EA | E12: =[8]summary!E11 -> 55 | F12: =[8]summary!F11 -> 1 | G12: =E12*F12 -> 55
A13: 9 | B13: غسالة مابي 19كيلو +11 كيلو | C13: Washing Machine Mabe 19k LMA79115V BC40 | D13: EA | E13: =[8]summary!E12 -> 650 | F13: =[8]summary!F12 -> 6 | G13: =E13*F13 -> 3900
A14: 10 | B14: نشافة مابي 10-20كيلو | C14: Dryer Machine Mabe 10-20k SME26N5XNBCTOO | D14: EA | E14: =[8]summary!E13 -> 650 | F14: =[8]summary!F13 -> 6 | G14: =E14*F14 -> 3900
A16: Total | F16: =SUM(F5:F14) -> 43 | G16: =SUM(G5:G14) -> 9534.68

Sheet Work Tools Store   
A2: =TODAY() -> 46123
A3: مخزن معدات العمل / Work Tools Store
A4: ت | B4: اسم المادة | C4: Item | D4: الوحدة Unit | E4: Unit price سعر الوحدة | F4: الكمية Qty | G4: Total المجموع | H4: Remark ملاحظة
A5: 1 | B5: مكينة لحيم صغيرة | C5: Small Welding Machine MAKITA ARC 950 | D5: EA | E5: =[9]Summary!E5 -> 55 | F5: =[9]Summary!F5 -> 3 | G5: =E5*F5 -> 165
A6: 2 | B6: كوسرة كبيرة ديوالت | C6: Grinder Machine Big Dewalt | D6: EA | E6: =[9]Summary!E6 -> 80 | F6: =[9]Summary!F6 -> 2 | G6: =E6*F6 -> 160
A7: 3 | B7: كوسرة صغيرة ديوالت | C7: Grinder Machine Small Dewalt DWE4010T | D7: EA | E7: =[9]Summary!E7 -> 39 | F7: =[9]Summary!F7 -> 2 | G7: =E7*F7 -> 78
A8: 4 | B8: كتر ساندوج بنل 10سم | C8: Cutter Sandwich panel 10cm Dewalt | D8: EA | E8: =[9]Summary!E8 -> 200 | F8: =[9]Summary!F8 -> 1 | G8: =E8*F8 -> 200
A9: 5 | B9: كتر حدادين ديوالت | C9: Cutter Smiths Dewalt | D9: EA | E9: =[9]Summary!E9 -> 130 | F9: =[9]Summary!F9 -> 0 | G9: =E9*F9 -> 0
A10: 6 | B10: جكسة صغيرة | C10: Small Jigsaw parkside parkside Pstd800b | D10: EA | E10: =[9]Summary!E10 -> 100 | F10: =[9]Summary!F10 -> 1 | G10: =E10*F10 -> 100
A11: 7 | B11: كتر زاوية بي في سي ديوالت | C11: Cutter Angle PVC Dewalt | D11: EA | E11: =[9]Summary!E11 -> 700 | F11: =[9]Summary!F11 -> 0 | G11: =E11*F11 -> 0
A12: 8 | B12: فايبريتر كونكريت | C12: Concrete Vibrater | D12: EA | E12: =[9]Summary!E12 -> 145 | F12: =[9]Summary!F12 -> 0 | G12: =E12*F12 -> 0
A13: 9 | B13: منشار ديوالت كهربائي 18فولط | C13: Dewalt DCS371N-XJ Sierra De Banda | D13: EA | E13: =[9]Summary!E13 -> 430 | F13: =[9]Summary!F13 -> 0 | G13: =E13*F13 -> 0
A14: 10 | B14: كوسرة كبيرة نوعية ماكيتا | C14: Big Grinder Machine Makita RED | D14: EA | E14: =[9]Summary!E14 -> 97 | F14: =[9]Summary!F14 -> 0 | G14: =E14*F14 -> 0
A15: 11 | B15: جكسة كبيرة شحن 560واط ديوالت | C15: Dewalt DCS380 M2 | D15: EA | E15: =[9]Summary!E15 -> 347 | F15: =[9]Summary!F15 -> 2 | G15: =E15*F15 -> 694
A16: 12 | B16: دريل صغير كهرباء 750واط ديوالت | C16: Dewalt DWD024K | D16: EA | E16: =[9]Summary!E16 -> 55 | F16: =[9]Summary!F16 -> 4 | G16: =E16*F16 -> 220
... A49: 45 | B49: حادلة مربع صغيرة روبين | C49: Plate Compactor With EY-20 Engine Robin | D49: EA | E49: =[9]Summary!E49 -> 420 | F49: =[9]Summary!F49 -> 0 | G49: =E49*F49 -> 0
A51: Total | F51: =SUM(F5:F50) -> 57 | G51: =SUM(G5:G49) -> 8571

Sheet Sandwich , Plywood ,Vinyl
A2: =TODAY() -> 46123
A3: مخزن ساندوج , بليوود, فاينل , اليكوبون /Sandwich , Plywood Vinyl , Alucobond
A4: ت | B4: اسم المادة | C4: Subject Name | D4: الوحدة Unit | E4: Rate Per Unit القيمة لكل وحدة | F4: الكمية .Qty | G4: Total المجموع | H4: Remark ملاحظة
A5: 1 | B5: اليكوبوند ابيض 320*125سم 3م | C5: Alucobond White 3mm 125 320cm | D5: EA. | E5: =[10]Summary!E4 -> 25 | F5: =[10]Summary!F4 -> 1 | G5: =F5*E5 -> 25
A6: 2 | B6: سقف ثانوي المنيوم 60*60 ابيض | C6: Aluminum Ceiligs 60*60 white | D6: EA. | E6: =[10]Summary!E5 -> 3.33 | F6: =[10]Summary!F5 -> 0 | G6: =F6*E6 -> 0
A7: 3 | B7: زاوية سيراميك 270سم ستيل | C7: Angle Ceramic 270cm Steel | D7: EA. | E7: =[10]Summary!E6 -> 2.06 | F7: =[10]Summary!F6 -> 0 | G7: =F7*E7 -> 0
A8: 4 | B8: زاوية جبسم بورد 3م | C8: Angle Gypsum Board 3m | D8: EA. | E8: =[10]Summary!E7 -> 0.4 | F8: =[10]Summary!F7 -> 0 | G8: =F8*E8 -> 0
A9: 5 | B9: زاوية جبسم بورد مخرمة 270سم | C9: Angle Gypsum Board With Hole | D9: EA. | E9: =[10]Summary!E8 -> 0.5 | F9: =[10]Summary!F8 -> 0 | G9: =F9*E9 -> 0
A10: 6 | B10: زاوية لازارة بلاستيك | C10: Angle Internal Plastic | D10: EA. | E10: =[10]Summary!E9 -> 0.5 | F10: =[10]Summary!F9 -> 2 | G10: =F10*E10 -> 1
A11: 7 | B11: زاوية باركيه | C11: Angle Parket plastic floor 280Cm | D11: EA. | E11: =[10]Summary!E10 -> 2.25 | F11: =[10]Summary!F10 -> 0 | G11: =F11*E11 -> 0
A12: 8 | B12: ازارة بلاستيك عرض9سم طول 280سم | C12: Angle Plastic 9cm 280cm | D12: EA. | E12: =[10]Summary!E11 -> 2.5 | F12: =[10]Summary!F11 -> 0 | G12: =F12*E12 -> 0
A13: 9 | B13: ازارة بلاستيك اوف وايت عرض 10سم طول 280سم | C13: Angle Plastic Off white 10cm 280cm | D13: EA. | E13: =[10]Summary!E12 -> 2.75 | F13: =[10]Summary!F12 -> 0 | G13: =F13*E13 -> 0
A14: 10 | B14: سكة سقف ثانوي ابيض 3.6م | C14: Angle Secondary Ceilings 3.6m | D14: EA. | E14: =[10]Summary!E13 -> 4 | F14: =[10]Summary!F13 -> 0 | G14: =F14*E14 -> 0
A15: 11 | B15: زاوية سقف ثانوي ابيض 3م | C15: Angle Secondary Ceilings 3m | D15: EA. | E15: =[10]Summary!E14 -> 1.25 | F15: =[10]Summary!F14 -> 0 | G15: =F15*E15 -> 0
A16: 12 | B16: جوين T باركيه المنيوم 3م | C16: Angle T Aluminium 3cm 3m Parket Silver | D16: EA. | E16: =[10]Summary!E15 -> 2.39 | F16: =[10]Summary!F15 -> 0 | G16: =F16*E16 -> 0
... A26: 22 | B26: جوين فاينل ازرق | C26: Blue Joint Vinyl | D26: Roll | E26: =[10]Summary!E25 -> 27 | F26: =[10]Summary!F25 -> 35.42 | G26: =F26*E26 -> 956.34
A27: 23 | B27: جوين فاينل رصاصي | C27: Gray Joint vinyl | D27: Roll | E27: =[10]Summary!E66 -> 27 | F27: =[10]Summary!F66 -> 70.23 | G27: =F27*E27 -> 1896.21
A28: 24 | B28: سي جنل جبسم بورد 3متر 4*1سم | C28: C Channel Gypsum Board 3mt 4*1cm | D28: EA. | E28: =[10]Summary!E27 -> 0.85 | F28: =[10]Summary!F27 -> 0 | G28: =F28*E28 -> 0
A29: 25 | B29: كرفان جاهز من تركيا | C29: Caravan 3*10mt | D29: EA. | E29: =[10]Summary!E28 -> 4820 | F29: =[10]Summary!F28 -> 1 | G29: =F29*E29 -> 4820
A30: 26 | B30: شيش سقف ثانوي 1م | C30: ceiling hanger wire 1m | D30: EA. | E30: =[10]Summary!E29 -> 0.27 | F30: =[10]Summary!F29 -> 0 | G30: =F30*E30 -> 0
A31: 27 | B31: شيش سقف ثانوي60 سم | C31: ceiling hanger wire 60cm | D31: Bundle | E31: =[10]Summary!E30 -> 0 | F31: =[10]Summary!F30 -> 0 | G31: =F31*E31 -> 0
A32: 28 | B32: سكة سقف ثانوي 320سم اسود | C32: ceilings main beam320cm a black line | D32: EA. | E32: =[10]Summary!E31 -> 0.3 | F32: =[10]Summary!F31 -> 0 | G32: =F32*E32 -> 0
A33: 29 | B33: سكة سقف ثانوي 120سم ابيض | C33: ceilings main beam 120cm White | D33: EA. | E33: =[10]Summary!E32 -> 0.65 | F33: =[10]Summary!F32 -> 275 | G33: =F33*E33 -> 178.75
A34: 30 | B34: سكة سقف ثانوي 360سم ابيض | C34: ceilings main beam 360cm White | D34: EA. | E34: =[10]Summary!E33 -> 3.25 | F34: =[10]Summary!F33 -> 1 | G34: =F34*E34 -> 3.25
A35: 31 | B35: سكة سقف ثانوي 60سم يحتوي على خط اسود | C35: ceilings main beam 60cm a black line | D35: EA. | E35: =[10]Summary!E34 -> 0.65 | F35: =[10]Summary!F34 -> 525 | G35: =F35*E35 -> 341.25
A36: 32 | B36: سكة سقف ثانوي 60سم ابيض | C36: ceilings main beam 60cm White | D36: EA. | E36: =[10]Summary!E35 -> 3.5 | F36: =[10]Summary!F35 -> 380 | G36: =F36*E36 -> 1330
A37: 33 | B37: سكة سقف ثانوي120سم يحتوي على خط اسود | C37: ceilings main beam120cm a black line | D37: EA. | E37: =[10]Summary!E36 -> 0.65 | F37: =[10]Summary!F36 -> 1505 | G37: =F37*E37 -> 978.25
A38: 34 | B38: سمنت بورد 12ملم | C38: cement board 12mm | D38: EA. | E38: =[10]Summary!E37 -> 32 | F38: =[10]Summary!F37 -> 0 | G38: =F38*E38 -> 0
A39: 35 | B39: سمنت بورد 18ملم | C39: cement board 18mm | D39: EA. | E39: =[10]Summary!E38 -> 34 | F39: =[10]Summary!F38 -> 14 | G39: =F39*E39 -> 476
... A54: 50 | B54: طربوش اندوفيلا | C54: Cowl Onduvilla | D54: EA. | E54: =[10]Summary!E53 -> 4 | F54: =[10]Summary!F53 -> 1041 | G54: =F54*E54 -> 4164
A55: 51 | B55: جوين فاينل كريمي (حليبي) | C55: Joint Cream Vinyl | D55: Roll | E55: =[10]Summary!E76 -> 27 | F55: =[10]Summary!F76 -> 1 | G55: =F55*E55 -> 27
A56: 52 | B56: باب براد | C56: Door Freezer | D56: EA. | E56: =[10]Summary!E55 -> 0 | F56: =[10]Summary!F55 -> 3 | G56: =F56*E56 -> 0
A57: 53 | B57: حافات اندوفيلا 100*30سم | C57: Edge Onduvilla 100*30cm | D57: EA. | E57: =[10]Summary!E56 -> 0 | F57: =[10]Summary!F56 -> 5866 | G57: =F57*E57 -> 0
A58: 54 | B58: عكس للازارة | C58: Elbow angle Plastic | D58: EA. | E58: =[10]Summary!E57 -> 0.75 | F58: =[10]Summary!F57 -> 0 | G58: =F58*E58 -> 0
A59: 55 | B59: حديد قاعدة ابو برغي (ستاند) | C59: FFH 15cm Pedestals And Gaskets | D59: EA. | E59: =[10]Summary!E58 -> 2.15 | F59: =[10]Summary!F58 -> 0 | G59: =F59*E59 -> 0
A60: 56 | B60: كاربت ارضي 50*50سم رصاصي مقلم اسود | C60: Floor Carpet 50*50cm L.C.T | D60: EA. | E60: =[10]Summary!E59 -> 3.375 | F60: =[10]Summary!F59 -> 0 | G60: =F60*E60 -> 0
A61: 57 | B61: ايطار باب خشب | C61: Frame Wood Door | D61: EA. | E61: =[10]Summary!E60 -> 0 | F61: =[10]Summary!F60 -> 300 | G61: =F61*E61 -> 0
A62: 58 | B62: عازل صوف زجاجي 10سم 5*1.2m 6m² | C62: Glass Wool Insulator aluminum 10cm 5*1.5m 2.88m² | D62: EA. | E62: =[10]Summary!E61 -> 30.3 | F62: =[10]Summary!F61 -> 120 | G62: =F62*E62 -> 3636
A63: 59 | B63: عازل صوف زجاجي 15سم 5 *1.2m 6m² | C63: Glass Wool Insulator Vinyl 15cm 5*1.2m 6m² | D63: EA. | E63: =[10]Summary!E62 -> 25.8 | F63: =[10]Summary!F62 -> 36 | G63: =F63*E63 -> 928.8
A64: 60 | B64: صوف زجاجي صغير رولات | C64: Glass wool small roller | D64: EA. | E64: =[10]Summary!E63 -> 24 | F64: =[10]Summary!F63 -> 14 | G64: =F64*E64 -> 336
...

Sheet Safety Store
A2: =TODAY() -> 46123
A3: مخزن سيفتي / Safety Store
A4: ت | B4: (اسم المادة ) | C4: (Subject Name) | D4: الوحدة Unit | E4: Rate Per Unit القيمة لكل وحدة | F4: الكمية Qty | G4: Total المجموع | H4: Remark ملاحظة
A5: 1 | B5: خوذة سيفتي | C5: Helmet Safety MSA | D5: Nos | E5: ='[11] Helmet Safety MSA '!$E$42 -> 5 | F5: ='[11] Helmet Safety MSA '!$I$42 -> 9 | G5: =E5*F5 -> 45
A6: 2 | B6: خوذة سيفتي | C6: Helmet Safety SM905 | D6: Nos | E6: ='[11] Helmet Safety SM905 '!$E$31 -> 5 | F6: ='[11] Helmet Safety SM905 '!$I$31 -> 0 | G6: =E6*F6 -> 0
A7: 3 | B7: جيرسي حاجز بلاستك | C7: Jersey Barrier Plastic used | D7: Nos | E7: ='[11] Jersey Barrier Plastic'!$E$31 -> 55 | F7: ='[11] Jersey Barrier Plastic'!$I$31 -> 0 | G7: =E7*F7 -> 0
A8: 4 | B8: لايت سفتي لمخروط السيفتي مع قاعدة | C8: light Recharge For Cone | D8: Nos | E8: ='[11] light Recharge For Cone'!$E$31 -> 18 | F8: ='[11] light Recharge For Cone'!$I$31 -> 0 | G8: =E8*F8 -> 0
A9: 5 | B9: كفوف طبية | C9: Medical Gloves | D9: Nos | E9: ='[11] Medical Gloves '!$E$31 -> 5 | F9: ='[11] Medical Gloves '!$I$31 -> 0 | G9: =E9*F9 -> 0
A10: 6 | B10: مناظر سيفتي | C10: Safety lenses Elvex SG-37C | D10: Nos | E10: ='[11] Safety lenses Elvex SG-37C'!$E$31 -> 10 | F10: ='[11] Safety lenses Elvex SG-37C'!$I$31 -> 0 | G10: =E10*F10 -> 0
A11: 7 | B11: شريط دواء اموكسيلين | C11: Amoxillin 500mg | D11: Nos | E11: ='[11]Amoxillin 500mg'!$E$57 -> 2.41 | F11: ='[11]Amoxillin 500mg'!$I$57 -> 0 | G11: =E11*F11 -> 0
A12: 8 | B12: شريط دواء انايربيكس | C12: Anaerobex 500mg | D12: Nos | E12: ='[11]Anaerobex 500mg'!$E$57 -> 4.13 | F12: ='[11]Anaerobex 500mg'!$I$57 -> 0 | G12: =E12*F12 -> 0
A13: 9 | B13: اسبرين | C13: Apron Welding | D13: Nos | E13: ='[11]Apron Welding '!$E$31 -> 11 | F13: ='[11]Apron Welding '!$I$31 -> 3 | G13: =E13*F13 -> 33
A14: 10 | B14: صدرية لحام | C14: Azitro 500mg | D14: Nos | E14: ='[11]Azitro 500mg '!$E$31 -> 2.5 | F14: ='[11]Azitro 500mg '!$I$31 -> 0 | G14: =E14*F14 -> 0
A15: 11 | B15: ستيكر علامة fnc كبيرة | C15: Big Sticker Alucoband FNC | D15: Nos | E15: ='[11]Big Sticker Alucoband FNC '!$E$31 -> 22.5 | F15: ='[11]Big Sticker Alucoband FNC '!$I$31 -> 12 | G15: =E15*F15 -> 270
A16: 12 | B16: مناظر سيفتي اسود | C16: Black Safety lenses | D16: Nos | E16: ='[11]Black Safety lenses'!$E$42 -> 2.5 | F16: ='[11]Black Safety lenses'!$I$42 -> 65 | G16: =E16*F16 -> 162.5
A17: 13 | B17: ستيكر اصفر + اسود اركان | C17: Black+Yellow Glue Sticker | D17: Nos | E17: ='[11]Black+Yellow Glue Sticker '!$E$116 -> 2.5 | F17: ='[11]Black+Yellow Glue Sticker '!$I$116 -> 12 | G17: =E17*F17 -> 30
A18: 14 | B18: كفوف عمال ازرق | C18: Blue Gloves worker | D18: Nos | E18: ='[11]Blue Gloves worker'!$E$124 -> 0.4166 | F18: ='[11]Blue Gloves worker'!$I$124 -> 384 | G18: =E18*F18 -> 159.9744
A19: 15 | B19: شريط تحذير لرفع الكيبلات برتقالي | C19: Caution Tape Electrical Orange | D19: Nos | E19: ='[11]Caution Tape Electrical Orange'!$E$32 -> 24 | F19: ='[11]Caution Tape Electrical Orange'!$I$32 -> 0 | G19: =E19*F19 -> 0
A20: 16 | B20: شريط تحذير لرفع الكيبلات احمر | C20: Caution Tape Electrical RED | D20: Nos | E20: ='[11]Caution Tape Electrical RED'!$E$32 -> 20 | F20: ='[11]Caution Tape Electrical RED'!$I$32 -> 0 | G20: =E20*F20 -> 0
A21: 17 | B21: شريط تحذير ماء | C21: Caution Tape Water Blue | D21: Nos | E21: ='[11]Caution Tape Wster Blue'!$E$32 -> 10 | F21: ='[11]Caution Tape Wster Blue'!$I$32 -> 8 | G21: =E21*F21 -> 80
A22: 18 | B22: شريط تحذير لرفع الكيبلات اصفر | C22: Caution Tape Electrical Yallow | D22: Nos | E22: ='[11]Caution Tape Electrical Yellow'!$E$42 -> 10 | F22: ='[11]Caution Tape Electrical Yellow'!$I$42 -> 9 | G22: =E22*F22 -> 90
A23: 19 | B23: خوذة سيفتي دائري msa | C23: Circular Helmet Safety MSA | D23: Nos | E23: ='[11]Circular Helmet Safety MSA'!$E$42 -> 12 | F23: ='[11]Circular Helmet Safety MSA'!$I$42 -> 0 | G23: =E23*F23 -> 0
A24: 20 | B24: جهاز فحص اوكسجين ونبضات القلب | C24: Device For Check O2 Heart Beat | D24: Roll | E24: ='[11]Device For Check O2 Heart Beat '!$E$31 -> 10 | F24: ='[11]Device For Check O2 Heart Beat '!$I$31 -> 0 | G24: =E24*F24 -> 0
A25: 21 | B25: كفر لون ازرق للاحذية سفري | C25: Disposable Nylon Blue Shoes Cov | D25: Nos | E25: ='[11]Disposable Nylon Blue Shoes Cov'!$E$31 -> 0.0833 | F25: ='[11]Disposable Nylon Blue Shoes Cov'!$I$31 -> 0 | G25: =E25*F25 -> 0
A26: 22 | B26: كمامات طبية | C26: Disposable Procedural Face Mask | D26: Roll | E26: ='[11]Disposable Procedural Face Mask'!$E$95 -> 1.15 | F26: ='[11]Disposable Procedural Face Mask'!$I$95 -> 5 | G26: =E26*F26 -> 5.75
A27: 23 | B27: ستيكر لاصق دائري 80سم مع رسم نسر | C27: Eagle Sticker 80cm Circular | D27: Nos | E27: ='[11]Eagle Sticker 80cm Circular'!$E$31 -> 20 | F27: ='[11]Eagle Sticker 80cm Circular'!$I$31 -> 0 | G27: =E27*F27 -> 0
A28: 24 | B28: كاتم ضجيج ورث | C28: Ear Muff With Extra Thick | D28: Nos | E28: ='[11]Ear Muff With Extra Thick'!$E$31 -> 8 | F28: ='[11]Ear Muff With Extra Thick'!$I$31 -> 2 | G28: =E28*F28 -> 16
A29: 25 | B29: نقالة الطوارئ | C29: Emergency Stretcher | D29: Nos | E29: ='[11]Filter Face Mask Painter'!$E$31 -> 9 | F29: ='[11]Filter Face Mask Painter'!$I$31 -> 0 | G29: =E29*F29 -> 0
A30: 26 | B30: غسالة عيون | C30: EYE WASH | D30: Nos | E30: ='[11]EYE WASH '!$E$31 -> 550 | F30: ='[11]EYE WASH '!$I$31 -> 0 | G30: =E30*F30 -> 0
A31: 27 | B31: قناع وجه مع فلتر للصباغين | C31: Face Mask With filter Painter | D31: Nos | E31: ='[11]Face Mask With filter Painter '!$E$31 -> 23 | F31: ='[11]Face Mask With filter Painter '!$I$31 -> 0 | G31: =E31*F31 -> 0
A32: 28 | B32: كمامة طبية نوع n95 | C32: Face Msck N95 | D32: Nos | E32: ='[11]Face Msck N95'!$E$26 -> 4 | F32: ='[11]Face Msck N95'!$I$26 -> 11 | G32: =E32*F32 -> 44
A33: 29 | B33: واقي وجه | C33: Face Shild | D33: Nos | E33: ='[11]Face Shild '!$E$31 -> 1.027 | F33: ='[11]Face Shild '!$I$31 -> 0 | G33: =E33*F33 -> 0
A34: 30 | B34: واقي وجه يتركب على خوذة مع قاعدة | C34: Face Shild Grinder With Base | D34: Nos | E34: ='[11]Face Shild Grinder With Base '!$E$88 -> 0 | F34: ='[11]Face Shild Grinder With Base '!$I$88 -> 7 | G34: =E34*F34 -> 0
A35: 31 | B35: طفايات حريق (تعبئة) | C35: Fill Fire Extinguisher | D35: Nos | E35: ='[11]Fill Fire Extinguisher '!$E$90 -> 0 | F35: ='[11]Fill Fire Extinguisher '!$I$90 -> 0 | G35: =E35*F35 -> 0
A36: 32 | B36: فلتر قناع سفتي صباغين 6001-3M | C36: Filter Face Mask Painter | D36: Nos | E36: ='[11]Filter Face Mask Painter'!$E$31 -> 9 | F36: ='[11]Filter Face Mask Painter'!$I$31 -> 0 | G36: =E36*F36 -> 0
A37: 33 | B37: بطانية حريق سيفتي | C37: Fire Blanket 1.2 1.8mt | D37: Nos | E37: ='[11]Fire Blanket 1.2 1.8mt'!$E$26 -> 25 | F37: ='[11]Fire Blanket 1.2 1.8mt'!$I$26 -> 0 | G37: =E37*F37 -> 0
A38: 34 | B38: طفايات حريق جديد | C38: Fire Extinguisher 1k HBR | D38: Nos | E38: ='[11]Fire Extinguisher 1k HBR'!$E$26 -> 8.5 | F38: ='[11]Fire Extinguisher 1k HBR'!$I$26 -> 0 | G38: =E38*F38 -> 0
A39: 35 | B39: طفايات حريق جديد | C39: Fire Extinguisher 1k With Hose | D39: Nos | E39: ='[11]Fire Extinguisher 1k With Hose'!$E$26 -> 30 | F39: ='[11]Fire Extinguisher 1k With Hose'!$I$26 -> 0 | G39: =E39*F39 -> 0
A40: 36 | B40: طفايات حريق جديد | C40: Fire Extinguisher 25k | D40: Nos | E40: ='[11]Fire Extinguisher 25k '!$E$26 -> 0 | F40: ='[11]Fire Extinguisher 25k '!$I$26 -> 0 | G40: =E40*F40 -> 0
A41: 37 | B41: طفايات حريق جديد | C41: Fire Extinguisher 3lt Wet Chemi | D41: Nos | E41: ='[11]Fire Extinguisher 3lt Wet Chemi'!$E$26 -> 75 | F41: ='[11]Fire Extinguisher 3lt Wet Chemi'!$I$26 -> 0 | G41: =E41*F41 -> 0
...

Sheet General Construction Store
A2: =TODAY() -> 46123
A3: مخزن مواد بناء عامة / General Construction Store
A4: ت | B4: اسم المادة | C4: Subject Name | D4: Unit الوحدة | E4: Rate Per Unit القيمة لكل وحدة | F4: Qty. الكمية | G4: Total المجموع | H4: Remark ملاحظة
A5: 1 | B5: ثيل صناعي | C5: Artificial grass | D5: EA. | E5: =[12]Summary!E4 -> 2.6 | F5: =[12]Summary!F4 -> 0 | G5: =E5*F5 -> 0
A6: 2 | B6: اوراق A3 ابيض زيروكس | C6: A3 Paper Xerox | D6: EA. | E6: =[12]Summary!E5 -> 34 | F6: =[12]Summary!F5 -> 0 | G6: =E6*F6 -> 0
A7: 3 | B7: اوراق A4 ابيض زيروكس | C7: A4 Paper Xerox | D7: EA. | E7: =[12]Summary!E6 -> 16 | F7: =[12]Summary!F6 -> 0 | G7: =E7*F7 -> 0
A8: 4 | B8: باتري قلم حجم وسط | C8: AA Battery | D8: EA. | E8: =[12]Summary!E7 -> 6.2 | F8: =[12]Summary!F7 -> 0 | G8: =E8*F8 -> 0
A9: 5 | B9: مزيل لاصق 355ملم | C9: Adhesive & Grease Remover Goo G | D9: EA. | E9: =[12]Summary!E8 -> 12 | F9: =[12]Summary!F8 -> 0 | G9: =E9*F9 -> 0
A10: 6 | B10: كبريت زراعي | C10: Agricultural Sulfur | D10: EA. | E10: =[12]Summary!E9 -> 8.57 | F10: =[12]Summary!F9 -> 0 | G10: =E10*F10 -> 0
A11: 7 | B11: جهاز منقي الهواء | C11: air filter device | D11: EA. | E11: =[12]Summary!E10 -> 0 | F11: =[12]Summary!F10 -> 0 | G11: =E11*F11 -> 0
A12: 8 | B12: مانع انزلاق بلاستيك ازرق | C12: Anti Slip Bathroom Plastic | D12: EA. | E12: =[12]Summary!E11 -> 0.68 | F12: =[12]Summary!F11 -> 2 | G12: =E12*F12 -> 1.36
A13: 9 | B13: اسلاك شائكة | C13: Barbed Wires | D13: Roll | E13: =[12]Summary!E12 -> 20 | F13: =[12]Summary!F12 -> 925 | G13: =E13*F13 -> 18500
A14: 10 | B14: بيس بليت سكلة | C14: base plate | D14: EA. | E14: =[12]Summary!E13 -> 1.68 | F14: =[12]Summary!F13 -> 0 | G14: =E14*F14 -> 0
A15: 11 | B15: باتري 18فولط لدريل شحن | C15: Battery 18v For Recharge Drill | D15: EA. | E15: =[12]Summary!E14 -> 75 | F15: =[12]Summary!F14 -> 0 | G15: =E15*F15 -> 0
A16: 12 | B16: سكلة كبيرة | C16: Big Scaffold | D16: EA. | E16: =[12]Summary!E15 -> 1250 | F16: =[12]Summary!F15 -> 0 | G16: =E16*F16 -> 0
... A92: 88 | B92: قلم تصحيح ابيض | C92: White ink pen | D92: EA. | E92: =[12]Summary!E91 -> 1.25 | F92: =[12]Summary!F91 -> 0 | G92: =E92*F92 -> 0
A93: 89 | B93: ='[12]White Rope Ratchet '!$L$4 -> حبل ابيض للسخانات | C93: White Rope Ratchet | D93: EA. | E93: =[12]Summary!E92 -> 20.92 | F93: =[12]Summary!F92 -> 1 | G93: =E93*F93 -> 20.92
A94: 90 | B94: كونية لون ابيض | C94: White Sand Bag | D94: EA. | E94: =[12]Summary!E93 -> 0.101 | F94: =[12]Summary!F93 -> 371 | G94: =E94*F94 -> 37.471
A95: 91 | B95: ستيكر لاصق ابيض للبرغي نوع دائري MDF | C95: White Sticker Glue For Bolt MDF | D95: EA. | E95: =[12]Summary!E94 -> 0.098 | F95: =[12]Summary!F94 -> 192.5 | G95: =E95*F95 -> 18.865
A96: 92 | B96: ='[12]Wiper Rubber Plastic For Vinyl '!$L$4 -> ماسحة بلاستيك وربل للفاينل 55سم SGS | C96: Wiper Rubber Plastic For Vinyl | D96: EA. | E96: =[12]Summary!E95 -> 3.375 | F96: =[12]Summary!F95 -> 0 | G96: =E96*F96 -> 0
A97: 93 | B97: ='[12]Wood Handle Spade '!$L$4 -> يدة كرك خشب | C97: Wood Handle Spade | D97: EA. | E97: =[12]Summary!E96 -> 2.5 | F97: =[12]Summary!F96 -> 18 | G97: =E97*F97 -> 45
A98: 94 | B98: كيس بلدية | C98: Trash Bag black | D98: Pack. | E98: =[12]Summary!E97 -> 13 | F98: =[12]Summary!F97 -> 6 | G98: =E98*F98 -> 78
A99: 95 | B99: حبل نايلون مثل سنارة الصيد | C99: Nylon Rope | D99: Roll | E99: =[12]Summary!E98 -> 0 | F99: =[12]Summary!F98 -> 21 | G99: =E99*F99 -> 0
A100: 96 | B100: ماسحة صبورة | C100: Blackboard Rubber | D100: EA. | E100: =[12]Summary!E99 -> 1.25 | F100: =[12]Summary!F99 -> 22 | G100: =E100*F100 -> 27.5
A101: 97 | B101: صبورة ابيض 90*60*3.5 سم | C101: White Board FRD 90*60*3.5cm | D101: EA. | E101: =[12]Summary!E100 -> 15 | F101: =[12]Summary!F100 -> 0 | G101: =E101*F101 -> 0
A102: 98 | B102: جمفر بلاستيك 3سم 3م | C102: Chamfer Plastic 3cm 3m | D102: Nos | E102: =[12]Summary!E101 -> 1 | F102: =[12]Summary!F101 -> 47 | G102: =F102*E102 -> 47
A103: 99 | B103: هيسكو 1*5م | C103: Hesco 1*5m 5cells | D103: EA | E103: =[12]Summary!E102 -> 125 | F103: =[12]Summary!F102 -> 26 | G103: =F103*E103 -> 3250
A104: 100 | B104: هيسكو 0.6*3م | C104: Hesco 0.6mt*3m 5cells | D104: EA | E104: =[12]Summary!E103 -> 75 | F104: =[12]Summary!F103 -> 6 | G104: =F104*E104 -> 450
A105: 101 | B105: هيسكو 0.6*1.2م | C105: Hesco 0.6*1.2m 2cells | D105: EA | E105: =[12]Summary!E104 -> 15 | F105: =[12]Summary!F104 -> 1 | G105: =F105*E105 -> 15
A106: 102 | B106: هيسكو 1.1*9.9 م | C106: Hesco 1.1*9.9 mt 9cells | D106: EA | E106: =[12]Summary!E105 -> 138 | F106: =[12]Summary!F105 -> 7 | G106: =F106*E106 -> 966
A107: 103 | B107: هيسكو 1*2م | C107: Hesco 1*2m 2cells | D107: EA. | E107: =[12]Summary!E106 -> 15 | F107: =[12]Summary!F106 -> 831 | G107: =F107*E107 -> 12465
A108: 104 | B108: عربانة دفع تاير واحد | C108: Wagon Single Tire | D108: EA | E108: =[12]Summary!E107 -> 17.5 | F108: =[12]Summary!F107 -> 2 | G108: 35
A109: 105 | B109: حاوية مغلون 1200 لتر | C109: Trash Cans 1200Lt | D109: EA. | E109: ='[12]Orange Trash Cans 1100Lt Sabala'!$E$31 -> 362 | F109: ='[12]Orange Trash Cans 1100Lt Sabala'!$I$31 -> 2 | G109: =F109*E109 -> 724
A111: Total | F111: =SUM(F5:F109) -> 12498.65 | G111: =SUM(G5:G109) -> 46936.087

Sheet Cleaning Materials Store 
A2: =TODAY() -> 46123
A3: مخزن مواد تنظيف / Cleaning Materials Store
A4: ت | B4: اسم المادة | C4: Subject Name | D4: الوحدة Unit | E4: Rate per Unit | F4: الكمية .Qty | G4: total المجموع | H4: Remark ملاحظة
A5: 1 | B5: فرشاة تنظيف ناعم | C5: Brush Plastic Cleaner | D5: EA | E5: =[13]Summary!E4 -> 0.67 | F5: =[13]Summary!F4 -> 16 | G5: =E5*F5 -> 10.72
A6: 2 | B6: مكرافة مع مكنسة بلاستيك | C6: Brush Plastic With Shit | D6: EA | E6: =[13]Summary!E5 -> 2.739 | F6: =[13]Summary!F5 -> 5 | G6: =E6*F6 -> 13.695
A7: 3 | B7: منظف اسبيروكس متعدد الاستخدام | C7: Cleaner Asperox 750mm | D7: Pack. * 12P | E7: =[13]Summary!E6 -> 14.7 | F7: =[13]Summary!F6 -> 0 | G7: =E7*F7 -> 0
A8: 4 | B8: فرشاة تنظيف خشن | C8: Cleaning Rough Broom Brush | D8: EA | E8: =[13]Summary!E7 -> 1.02 | F8: =[13]Summary!F7 -> 0 | G8: =E8*F8 -> 0
A9: 5 | B9: منظف ارضيات ديتول 900مل | C9: Dettol Cleaner 900ml | D9: Pack. * 12P | E9: =[13]Summary!E8 -> 33.34 | F9: =[13]Summary!F8 -> 0 | G9: =E9*F9 -> 0
A10: 6 | B10: منظف فلاش ميكا | C10: Flash Cleaner Mega | D10: Pack. * 12P | E10: =[13]Summary!E9 -> 16 | F10: =[13]Summary!F9 -> 1.501 | G10: =E10*F10 -> 24.016
A11: 7 | B11: منظف زجاج 750ملم | C11: Glass Clenner 750ml | D11: EA | E11: =[13]Summary!E10 -> 0.493 | F11: =[13]Summary!F10 -> 16 | G11: =E11*F11 -> 7.888
A12: 8 | B12: عودة ماسحة + فرشاة خشبية | C12: Handle Wood Floor Wiper | D12: EA | E12: =[13]Summary!E11 -> 0.178 | F12: =[13]Summary!F11 -> 18 | G12: =E12*F12 -> 3.204
A13: 9 | B13: مبيد حشرات | C13: Insecticide 250ml Deltathor | D13: EA | E13: =[13]Summary!E12 -> 6.5 | F13: =[13]Summary!F12 -> 22 | G13: =E13*F13 -> 143
A14: 10 | B14: صابون سائل | C14: Liquid Soap 400g | D14: Pack. * 12P | E14: =[13]Summary!E13 -> 6.8 | F14: =[13]Summary!F13 -> 0 | G14: =E14*F14 -> 0
A15: 11 | B15: كحول 20لتر 100% | C15: Medicinal alcohol 20l %100 | D15: EA | E15: =[13]Summary!E14 -> 29 | F15: =[13]Summary!F14 -> 2 | G15: =E15*F15 -> 58
A16: 12 | B16: موب | C16: Mop | D16: EA | E16: =[13]Summary!E15 -> 32.52 | F16: =[13]Summary!F15 -> 0 | G16: =E16*F16 -> 0
... A19: 15 | B19: كلور باودر | C19: Chlorine Powder Spic 50k | D19: Pail | E19: =[13]Summary!E18 -> 250 | F19: =[13]Summary!F18 -> 2 | G19: =E19*F19 -> 500
A21: Total | F21: =SUM(F5:F19) -> 86.501 | G21: =SUM(G5:G19) -> 1076.523

Sheet Outside Area Cables
A1: =TODAY() -> 46123
A2: كابلات سقيفة المعمل (شبه مستعملة) /Outside Area Cables ( Like New )
A3: ت | B3: اسم المادة | C3: Item | D3: الوحدة Unit | E3: Unit price سعر الوحدة | F3: 20% Discounted Price | G3: الكمية Qty | H3: Total المجموع | I3: Type | J3: Remark ملاحظة
A4: 1 | B4: كيبل مسلح 5*50ملم | C4: Armoured Cable 5*50mm | D4: Mtr. | E4: =[14]Summary!E4 -> 14.25 | F4: =[14]Summary!F4 -> 11.4 | G4: =[14]Summary!G4 -> 22 | H4: =F4*G4 -> 250.8 | I4: Armoured Cable | J4: Roll 1
A5: 2 | B5: كيبل 1*150ملم | C5: Black Cable 1*150mm | D5: Mtr. | E5: =[14]Summary!E5 -> 29 | F5: =[14]Summary!F5 -> 23.2 | G5: =[14]Summary!G5 -> 0 | H5: =F5*G5 -> 0 | I5: Normal Cable | J5: Roll 2
A6: 3 | B6: كيبل 5*10ملم | C6: Black cable 5*10mm | D6: Mtr. | E6: =[14]Summary!E6 -> 29 | F6: =[14]Summary!F6 -> 23.2 | G6: =[14]Summary!G6 -> 35 | H6: =F6*G6 -> 812 | I6: Normal Cable | J6: Roll 3
A7: 4 | B7: كيبل 5*16ملم | C7: Black Cable 5*16mm | D7: Mtr. | E7: =[14]Summary!E7 -> 33 | F7: =[14]Summary!F7 -> 26.4 | G7: =[14]Summary!G7 -> 0 | H7: =F7*G7 -> 0 | I7: Normal Cable | J7: Roll 4
